Workbook
Name _Hlk122640495: 'Jan 2026'!$B$92
Name _Hlk126512593: 'Jan 2026'!#REF!

Sheet Jan 2026
E1: Teller Technologies Private Limited
E2: 2nd Floor, No.1 7th Cross, 2nd Block TC Palya Main Road CSB Bank ATM Akshaya Nagar Ramamurthi Nagar Bangalore-560016
E3: FORMS AND FORMATS
E4: Title: Stock Sheet
E5: Department | H5: STORES | K5: Version No. | M5: 0 | N5: Issued Date
E6: DOC. No. | H6: FM/STR/001 | K6: Supersedes | M6: NIL
E7: Next Review Date | K7: Effective date
A9: Type of Goods
A10: Storage Location | B10: Part Number | C10: Product Name | D10: Rate | E10: Unit | F10: Opening Stock | G10: 46023 | H10: 46024 | I10: 46025 | J10: 46026 | K10: 46027 | L10: 46028 | M10: 46029 | N10: 46030 | O10: 46031 | P10: 46032 | Q10: 46033 | R10: 46034 | S10: 46035 | T10: 46036 | U10: 46037 | V10: 46038 | W10: 46039 | X10: 46040 | Y10: 46041 | Z10: 46042 | AA10: 46043 | AB10: 46044 | AC10: 46045 | AD10: 46046 | AE10: 46047 | AF10: 46048 | AG10: 46049 | AH10: 46050 | AI10: 46051 | AJ10: 46052 | AK10: 46053 | AL10: Closing Stock | AM10: Minimum Stock | AN10: Re order level | AO10: Maximum Stock
A11: B2 | B11: KPD-0240003 | C11: Keypad - 1.1 - CE10 | F11: 23 | AL11: =F11+SUM(G11:AK11) -> 23
A12: B2 | B12: KPD-0240004 | C12: Keypad - 1.1 - CE1H | F12: 499 | AL12: =F12+SUM(G12:AK12) -> 499
A13: B2 | B13: KPD-0240005 | C13: Keypad - 1.1 - CE120 | F13: 25 | AL13: =F13+SUM(G13:AK13) -> 25
A14: B1 | B14: KPD-0240006 | C14: Keypad - 1.1 - CE12H | F14: 470 | AL14: =F14+SUM(G14:AK14) -> 470
A15: B2 | B15: KPD-0240007 | C15: Keypad - 1.1 - CE130 | F15: =10-5 -> 5 | AL15: =F15+SUM(G15:AK15) -> 5
A16: B2 | B16: KPD-0240008 | C16: Keypad - 1.1 - CE13H | F16: 10 | AL16: =F16+SUM(G16:AK16) -> 10
A17: B2 | B17: KPD-0240009 | C17: Keypad - 1.1 - CE140 | F17: 8 | AL17: =F17+SUM(G17:AK17) -> 8
A18: B2 | B18: KPD-0240010 | C18: Keypad - 1.1 - CE14H | F18: 9 | AL18: =F18+SUM(G18:AK18) -> 9
B19: KPD-0240011 | C19: Keypad - 1.1 - CE1230 | F19: 0 | AL19: =F19+SUM(G19:AK19) -> 0
A20: B1 | B20: KPD-0240012 | C20: Keypad - 1.1 - CE123H | F20: 239 | AL20: =F20+SUM(G20:AK20) -> 239
A21: B2 | B21: KPD-0240013 | C21: Keypad - 1.1 - CE1240 | F21: 9 | AL21: =F21+SUM(G21:AK21) -> 9
A22: B1 | B22: KPD-0240014 | C22: Keypad - 1.1 - CE124H | F22: 260 | AL22: =F22+SUM(G22:AK22) -> 260
A23: B2 | B23: KPD-0240015 | C23: Keypad - 1.1 - CE12430 | F23: =22+11+4 -> 37 | H23: 40 | AL23: =F23+SUM(G23:AK23) -> 77
A24: B2 | B24: KPD-0240016 | C24: Keypad - 1.1 - CE1234H | H24: =250-3 -> 247 | I24: -80 | O24: 9 | AL24: =F24+SUM(G24:AK24) -> 176
A25: B2 | B25: KPD-0240017 | C25: Keypad - 3.1 - OE1(0/H) | F25: 477 | AL25: =F25+SUM(G25:AK25) -> 477
A26: B2 | B26: KPD-0240018 | C26: Keypad - 3.1 - OE12(0/H) | F26: =387+6 -> 393 | AL26: =F26+SUM(G26:AK26) -> 393
A27: B3 | B27: KPD-0240019 | C27: Keypad - 3.1 - OE13(0/H) | F27: 12 | AL27: =F27+SUM(G27:AK27) -> 12
A28: B3 | B28: KPD-0240020 | C28: Keypad - 3.1 - OE14(0/H) | F28: 9 | AL28: =F28+SUM(G28:AK28) -> 9
A29: B2 | B29: KPD-0240021 | C29: Keypad - 3.1 - OE123(0/H) | F29: 8 | AL29: =F29+SUM(G29:AK29) -> 8
A30: B3 | B30: KPD-0240022 | C30: Keypad - 3.1 - OE124(0/H) | F30: 9 | AL30: =F30+SUM(G30:AK30) -> 9
A31: B3 | B31: KPD-0240023 | C31: Keypad - 3.1 - OE134(0/H) | F31: 9 | AL31: =F31+SUM(G31:AK31) -> 9
A32: B3 | B32: KPD-0240024 | C32: Keypad - 3.1 - OE1234(0/H) | F32: 12 | AL32: =F32+SUM(G32:AK32) -> 12
A33: B3 | B33: KPD-0240025 | C33: Keypad - 3.1 - VOE1(0/H) | F33: 2 | AL33: =F33+SUM(G33:AK33) -> 2
A34: B2 | B34: KPD-0240026 | C34: Keypad - 3.1 - VOE12(0/H) | F34: 410 | AL34: =F34+SUM(G34:AK34) -> 410
A35: B3 | B35: KPD-0240027 | C35: Keypad - 3.1 - VOE13(0/H) | F35: 7 | AL35: =F35+SUM(G35:AK35) -> 7
A36: B3 | B36: KPD-0240028 | C36: Keypad - 3.1 - VOE14(0/H) | F36: 12 | AL36: =F36+SUM(G36:AK36) -> 12
A37: B3 | B37: KPD-0240029 | C37: Keypad - 3.1 - VOE123(0/H) | F37: 9 | AL37: =F37+SUM(G37:AK37) -> 9
A38: B3 | B38: KPD-0240030 | C38: Keypad - 3.1 - VOE124(0/H) | F38: 9 | AL38: =F38+SUM(G38:AK38) -> 9
... A40: B3 | B40: KPD-0240032 | C40: Keypad - 3.1 - TE150 | F40: 83 | AL40: =F40+SUM(G40:AK40) -> 83
A41: B3 | B41: KPD-0240033 | C41: Keypad - 3.1 - TE10 | F41: 10 | O41: -1 | AL41: =F41+SUM(G41:AK41) -> 9
A42: B3 | B42: KPD-0240034 | C42: Keypad - 3.1 - HH (P/E)1 | F42: =383-212 -> 171 | I42: -80 | J42: -21 | L42: -29 | O42: -6 | Q42: 300 | R42: -51 | Y42: -20 | AA42: -3 | AC42: -20 | AH42: -11 | AI42: -6 | AJ42: =-69+-7 -> -76 | AL42: =F42+SUM(G42:AK42) -> 148
...

Sheet Feb 2026
E1: Teller Technologies Private Limited
E2: 2nd Floor, No.1 7th Cross, 2nd Block TC Palya Main Road CSB Bank ATM Akshaya Nagar Ramamurthi Nagar Bangalore-560016
E3: FORMS AND FORMATS
E4: Title: Stock Sheet
E5: Department | H5: STORES | K5: Version No. | M5: 0 | N5: Issued Date
E6: DOC. No. | H6: FM/STR/001 | K6: Supersedes | M6: NIL
E7: Next Review Date | K7: Effective date
A9: Type of Goods
A10: Storage Location | B10: Part Number | C10: Product Name | D10: Rate | E10: Unit | F10: Opening Stock | G10: 46054 | H10: 46055 | I10: 46056 | J10: 46057 | K10: 46058 | L10: 46059 | M10: 46060 | N10: 46061 | O10: 46062 | P10: 46063 | Q10: 46064 | R10: 46065 | S10: 46066 | T10: 46067 | U10: 46068 | V10: 46069 | W10: 46070 | X10: 46071 | Y10: 46072 | Z10: 46073 | AA10: 46074 | AB10: 46075 | AC10: 46076 | AD10: 46077 | AE10: 46078 | AF10: 46079 | AG10: 46080 | AH10: 46081 | AI10: Closing Stock | AJ10: Minimum Stock | AK10: Re order level | AL10: Maximum Stock
A11: B2 | B11: KPD-0240003 | C11: Keypad - 1.1 - CE10 | F11: ='Jan 2026'!AL11 -> 23 | AI11: =F11+SUM(G11:AH11) -> 23
A12: B2 | B12: KPD-0240004 | C12: Keypad - 1.1 - CE1H | F12: ='Jan 2026'!AL12 -> 499 | Y12: -1 | AI12: =F12+SUM(G12:AH12) -> 498
A13: B2 | B13: KPD-0240005 | C13: Keypad - 1.1 - CE120 | F13: ='Jan 2026'!AL13 -> 25 | AI13: =F13+SUM(G13:AH13) -> 25
A14: B1 | B14: KPD-0240006 | C14: Keypad - 1.1 - CE12H | F14: ='Jan 2026'!AL14 -> 470 | AI14: =F14+SUM(G14:AH14) -> 470
A15: B2 | B15: KPD-0240007 | C15: Keypad - 1.1 - CE130 | F15: ='Jan 2026'!AL15 -> 5 | J15: 160 | AG15: -87 | AI15: =F15+SUM(G15:AH15) -> 78
A16: B2 | B16: KPD-0240008 | C16: Keypad - 1.1 - CE13H | F16: ='Jan 2026'!AL16 -> 10 | AI16: =F16+SUM(G16:AH16) -> 10
A17: B2 | B17: KPD-0240009 | C17: Keypad - 1.1 - CE140 | F17: ='Jan 2026'!AL17 -> 8 | AI17: =F17+SUM(G17:AH17) -> 8
A18: B2 | B18: KPD-0240010 | C18: Keypad - 1.1 - CE14H | F18: ='Jan 2026'!AL18 -> 9 | AI18: =F18+SUM(G18:AH18) -> 9
B19: KPD-0240011 | C19: Keypad - 1.1 - CE1230 | F19: ='Jan 2026'!AL19 -> 0 | AI19: =F19+SUM(G19:AH19) -> 0
A20: B1 | B20: KPD-0240012 | C20: Keypad - 1.1 - CE123H | F20: ='Jan 2026'!AL20 -> 239 | AI20: =F20+SUM(G20:AH20) -> 239
A21: B2 | B21: KPD-0240013 | C21: Keypad - 1.1 - CE1240 | F21: ='Jan 2026'!AL21 -> 9 | AI21: =F21+SUM(G21:AH21) -> 9
A22: B1 | B22: KPD-0240014 | C22: Keypad - 1.1 - CE124H | F22: ='Jan 2026'!AL22 -> 260 | AI22: =F22+SUM(G22:AH22) -> 260
A23: B2 | B23: KPD-0240015 | C23: Keypad - 1.1 - CE12430 | F23: ='Jan 2026'!AL23 -> 77 | AI23: =F23+SUM(G23:AH23) -> 77
A24: B2 | B24: KPD-0240016 | C24: Keypad - 1.1 - CE1234H | F24: ='Jan 2026'!AL24 -> 176 | AH24: -143 | AI24: =F24+SUM(G24:AH24) -> 33
A25: B2 | B25: KPD-0240017 | C25: Keypad - 3.1 - OE1(0/H) | F25: ='Jan 2026'!AL25 -> 477 | AI25: =F25+SUM(G25:AH25) -> 477
A26: B2 | B26: KPD-0240018 | C26: Keypad - 3.1 - OE12(0/H) | F26: ='Jan 2026'!AL26 -> 393 | AI26: =F26+SUM(G26:AH26) -> 393
A27: B3 | B27: KPD-0240019 | C27: Keypad - 3.1 - OE13(0/H) | F27: ='Jan 2026'!AL27 -> 12 | I27: 75 | J27: -21 | AI27: =F27+SUM(G27:AH27) -> 66
A28: B3 | B28: KPD-0240020 | C28: Keypad - 3.1 - OE14(0/H) | F28: ='Jan 2026'!AL28 -> 9 | AI28: =F28+SUM(G28:AH28) -> 9
A29: B2 | B29: KPD-0240021 | C29: Keypad - 3.1 - OE123(0/H) | F29: ='Jan 2026'!AL29 -> 8 | AI29: =F29+SUM(G29:AH29) -> 8
A30: B3 | B30: KPD-0240022 | C30: Keypad - 3.1 - OE124(0/H) | F30: ='Jan 2026'!AL30 -> 9 | AI30: =F30+SUM(G30:AH30) -> 9
A31: B3 | B31: KPD-0240023 | C31: Keypad - 3.1 - OE134(0/H) | F31: ='Jan 2026'!AL31 -> 9 | AI31: =F31+SUM(G31:AH31) -> 9
A32: B3 | B32: KPD-0240024 | C32: Keypad - 3.1 - OE1234(0/H) | F32: ='Jan 2026'!AL32 -> 12 | AI32: =F32+SUM(G32:AH32) -> 12
A33: B3 | B33: KPD-0240025 | C33: Keypad - 3.1 - VOE1(0/H) | F33: ='Jan 2026'!AL33 -> 2 | AI33: =F33+SUM(G33:AH33) -> 2
A34: B2 | B34: KPD-0240026 | C34: Keypad - 3.1 - VOE12(0/H) | F34: ='Jan 2026'!AL34 -> 410 | AI34: =F34+SUM(G34:AH34) -> 410
A35: B3 | B35: KPD-0240027 | C35: Keypad - 3.1 - VOE13(0/H) | F35: ='Jan 2026'!AL35 -> 7 | AI35: =F35+SUM(G35:AH35) -> 7
A36: B3 | B36: KPD-0240028 | C36: Keypad - 3.1 - VOE14(0/H) | F36: ='Jan 2026'!AL36 -> 12 | AI36: =F36+SUM(G36:AH36) -> 12
A37: B3 | B37: KPD-0240029 | C37: Keypad - 3.1 - VOE123(0/H) | F37: ='Jan 2026'!AL37 -> 9 | AI37: =F37+SUM(G37:AH37) -> 9
A38: B3 | B38: KPD-0240030 | C38: Keypad - 3.1 - VOE124(0/H) | F38: ='Jan 2026'!AL38 -> 9 | AI38: =F38+SUM(G38:AH38) -> 9
A39: B3 | B39: KPD-0240031 | C39: Keypad - 3.1 - VOE134(0/H) | F39: ='Jan 2026'!AL39 -> 9 | AI39: =F39+SUM(G39:AH39) -> 9
... A41: B3 | B41: KPD-0240033 | C41: Keypad - 3.1 - TE10 | F41: ='Jan 2026'!AL41 -> 9 | AI41: =F41+SUM(G41:AH41) -> 9
A42: B3 | B42: KPD-0240034 | C42: Keypad - 3.1 - HH (P/E)1 | F42: ='Jan 2026'!AL42 -> 148 | H42: -17 | J42: =-9+-21 -> -30 | O42: -2 | P42: -1 | S42: -31 | W42: -36 | AC42: -31 | AG42: 200 | AH42: -100 | AI42: =F42+SUM(G42:AH42) -> 100
...

Sheet March 2026
E1: Teller Technologies Private Limited
E2: 2nd Floor, No.1 7th Cross, 2nd Block TC Palya Main Road CSB Bank ATM Akshaya Nagar Ramamurthi Nagar Bangalore-560016
E3: FORMS AND FORMATS
E4: Title: Stock Sheet
E5: Department | H5: STORES | K5: Version No. | M5: 0 | N5: Issued Date
E6: DOC. No. | H6: FM/STR/001 | K6: Supersedes | M6: NIL
E7: Next Review Date | K7: Effective date
A9: Type of Goods
A10: Storage Location | B10: Part Number | C10: Product Name | D10: Rate | E10: Unit | F10: Opening Stock | G10: 46082 | H10: 46083 | I10: 46084 | J10: 46085 | K10: 46086 | L10: 46087 | M10: 46088 | N10: 46089 | O10: 46090 | P10: 46091 | Q10: 46092 | R10: 46093 | S10: 46094 | T10: 46095 | U10: 46096 | V10: 46097 | W10: 46098 | X10: 46099 | Y10: 46100 | Z10: 46101 | AA10: 46102 | AB10: 46103 | AC10: 46104 | AD10: 46105 | AE10: 46106 | AF10: 46107 | AG10: 46108 | AH10: 46109 | AI10: 46110 | AJ10: 46111 | AK10: 46112 | AL10: Closing Stock | AM10: Minimum Stock | AN10: Re order level | AO10: Maximum Stock
A11: B2 | B11: KPD-0240003 | C11: Keypad - 1.1 - CE10 | F11: ='Feb 2026'!AI11 -> 23 | AL11: =F11+SUM(G11:AH11) -> 23
A12: B2 | B12: KPD-0240004 | C12: Keypad - 1.1 - CE1H | F12: ='Feb 2026'!AI12 -> 498 | Z12: -1 | AD12: -26 | AG12: -21 | AL12: =F12+SUM(G12:AH12) -> 450
A13: B2 | B13: KPD-0240005 | C13: Keypad - 1.1 - CE120 | F13: ='Feb 2026'!AI13 -> 25 | AL13: =F13+SUM(G13:AH13) -> 25
A14: B1 | B14: KPD-0240006 | C14: Keypad - 1.1 - CE12H | F14: ='Feb 2026'!AI14 -> 470 | AL14: =F14+SUM(G14:AH14) -> 470
A15: B2 | B15: KPD-0240007 | C15: Keypad - 1.1 - CE130 | F15: ='Feb 2026'!AI15 -> 78 | M15: -5 | AL15: =F15+SUM(G15:AH15) -> 73
A16: B2 | B16: KPD-0240008 | C16: Keypad - 1.1 - CE13H | F16: ='Feb 2026'!AI16 -> 10 | AL16: =F16+SUM(G16:AH16) -> 10
A17: B2 | B17: KPD-0240009 | C17: Keypad - 1.1 - CE140 | F17: ='Feb 2026'!AI17 -> 8 | AL17: =F17+SUM(G17:AH17) -> 8
A18: B2 | B18: KPD-0240010 | C18: Keypad - 1.1 - CE14H | F18: ='Feb 2026'!AI18 -> 9 | AL18: =F18+SUM(G18:AH18) -> 9
B19: KPD-0240011 | C19: Keypad - 1.1 - CE1230 | F19: ='Feb 2026'!AI19 -> 0 | AL19: =F19+SUM(G19:AH19) -> 0
A20: B1 | B20: KPD-0240012 | C20: Keypad - 1.1 - CE123H | F20: ='Feb 2026'!AI20 -> 239 | AL20: =F20+SUM(G20:AH20) -> 239
A21: B2 | B21: KPD-0240013 | C21: Keypad - 1.1 - CE1240 | F21: ='Feb 2026'!AI21 -> 9 | AL21: =F21+SUM(G21:AH21) -> 9
A22: B1 | B22: KPD-0240014 | C22: Keypad - 1.1 - CE124H | F22: ='Feb 2026'!AI22 -> 260 | AL22: =F22+SUM(G22:AH22) -> 260
A23: B2 | B23: KPD-0240015 | C23: Keypad - 1.1 - CE12430 | F23: ='Feb 2026'!AI23 -> 77 | AL23: =F23+SUM(G23:AH23) -> 77
A24: B2 | B24: KPD-0240016 | C24: Keypad - 1.1 - CE1234H | F24: ='Feb 2026'!AI24 -> 33 | O24: -20 | AL24: =F24+SUM(G24:AH24) -> 13
A25: B2 | B25: KPD-0240017 | C25: Keypad - 3.1 - OE1(0/H) | F25: ='Feb 2026'!AI25 -> 477 | AL25: =F25+SUM(G25:AH25) -> 477
A26: B2 | B26: KPD-0240018 | C26: Keypad - 3.1 - OE12(0/H) | F26: ='Feb 2026'!AI26 -> 393 | AL26: =F26+SUM(G26:AH26) -> 393
A27: B3 | B27: KPD-0240019 | C27: Keypad - 3.1 - OE13(0/H) | F27: ='Feb 2026'!AI27 -> 66 | M27: =-2+-2 -> -4 | AL27: =F27+SUM(G27:AH27) -> 62
A28: B3 | B28: KPD-0240020 | C28: Keypad - 3.1 - OE14(0/H) | F28: ='Feb 2026'!AI28 -> 9 | AL28: =F28+SUM(G28:AH28) -> 9
A29: B2 | B29: KPD-0240021 | C29: Keypad - 3.1 - OE123(0/H) | F29: ='Feb 2026'!AI29 -> 8 | AL29: =F29+SUM(G29:AH29) -> 8
A30: B3 | B30: KPD-0240022 | C30: Keypad - 3.1 - OE124(0/H) | F30: ='Feb 2026'!AI30 -> 9 | AL30: =F30+SUM(G30:AH30) -> 9
A31: B3 | B31: KPD-0240023 | C31: Keypad - 3.1 - OE134(0/H) | F31: ='Feb 2026'!AI31 -> 9 | AL31: =F31+SUM(G31:AH31) -> 9
A32: B3 | B32: KPD-0240024 | C32: Keypad - 3.1 - OE1234(0/H) | F32: ='Feb 2026'!AI32 -> 12 | AL32: =F32+SUM(G32:AH32) -> 12
A33: B3 | B33: KPD-0240025 | C33: Keypad - 3.1 - VOE1(0/H) | F33: ='Feb 2026'!AI33 -> 2 | Z33: -1 | AL33: =F33+SUM(G33:AH33) -> 1
A34: B2 | B34: KPD-0240026 | C34: Keypad - 3.1 - VOE12(0/H) | F34: ='Feb 2026'!AI34 -> 410 | AL34: =F34+SUM(G34:AH34) -> 410
A35: B3 | B35: KPD-0240027 | C35: Keypad - 3.1 - VOE13(0/H) | F35: ='Feb 2026'!AI35 -> 7 | AL35: =F35+SUM(G35:AH35) -> 7
A36: B3 | B36: KPD-0240028 | C36: Keypad - 3.1 - VOE14(0/H) | F36: ='Feb 2026'!AI36 -> 12 | AL36: =F36+SUM(G36:AH36) -> 12
A37: B3 | B37: KPD-0240029 | C37: Keypad - 3.1 - VOE123(0/H) | F37: ='Feb 2026'!AI37 -> 9 | AL37: =F37+SUM(G37:AH37) -> 9
A38: B3 | B38: KPD-0240030 | C38: Keypad - 3.1 - VOE124(0/H) | F38: ='Feb 2026'!AI38 -> 9 | AL38: =F38+SUM(G38:AH38) -> 9
A39: B3 | B39: KPD-0240031 | C39: Keypad - 3.1 - VOE134(0/H) | F39: ='Feb 2026'!AI39 -> 9 | AL39: =F39+SUM(G39:AH39) -> 9
A40: B3 | B40: KPD-0240032 | C40: Keypad - 3.1 - TE150 | F40: ='Feb 2026'!AI40 -> 83 | AL40: =F40+SUM(G40:AH40) -> 83
A41: B3 | B41: KPD-0240033 | C41: Keypad - 3.1 - TE10 | F41: ='Feb 2026'!AI41 -> 9 | AL41: =F41+SUM(G41:AH41) -> 9
...

Sheet April 2026
E1: Teller Technologies Private Limited
E2: 2nd Floor, No.1 7th Cross, 2nd Block TC Palya Main Road CSB Bank ATM Akshaya Nagar Ramamurthi Nagar Bangalore-560016
E3: FORMS AND FORMATS
E4: Title: Stock Sheet
E5: Department | H5: STORES | K5: Version No. | M5: 0 | N5: Issued Date
E6: DOC. No. | H6: FM/STR/001 | K6: Supersedes | M6: NIL
E7: Next Review Date | K7: Effective date
A9: Type of Goods
A10: Storage Location | B10: Part Number | C10: Product Name | D10: Rate | E10: Unit | F10: Opening Stock | G10: 46113 | H10: 46114 | I10: 46115 | J10: 46116 | K10: 46117 | L10: 46118 | M10: 46119 | N10: 46120 | O10: 46121 | P10: 46122 | Q10: 46123 | R10: 46124 | S10: 46125 | T10: 46126 | U10: 46127 | V10: 46128 | W10: 46129 | X10: 46130 | Y10: 46131 | Z10: 46132 | AA10: 46133 | AB10: 46134 | AC10: 46135 | AD10: 46136 | AE10: 46137 | AF10: 46138 | AG10: 46139 | AH10: 46140 | AI10: 46141 | AJ10: 46142 | AK10: Closing Stock | AL10: Minimum Stock | AM10: Re order level | AN10: Maximum Stock
A11: B2 | B11: KPD-0240003 | C11: Keypad - 1.1 - CE10 | F11: ='Feb 2026'!AI11 -> 23 | AK11: =F11+SUM(G11:AH11) -> 23
A12: B2 | B12: KPD-0240004 | C12: Keypad - 1.1 - CE1H | F12: ='Feb 2026'!AI12 -> 498 | L12: -24 | M12: -2 | AK12: =F12+SUM(G12:AH12) -> 472
A13: B2 | B13: KPD-0240005 | C13: Keypad - 1.1 - CE120 | F13: ='Feb 2026'!AI13 -> 25 | AK13: =F13+SUM(G13:AH13) -> 25
A14: B1 | B14: KPD-0240006 | C14: Keypad - 1.1 - CE12H | F14: ='Feb 2026'!AI14 -> 470 | AK14: =F14+SUM(G14:AH14) -> 470
A15: B2 | B15: KPD-0240007 | C15: Keypad - 1.1 - CE130 | F15: ='Feb 2026'!AI15 -> 78 | AK15: =F15+SUM(G15:AH15) -> 78
A16: B2 | B16: KPD-0240008 | C16: Keypad - 1.1 - CE13H | F16: ='Feb 2026'!AI16 -> 10 | AK16: =F16+SUM(G16:AH16) -> 10
A17: B2 | B17: KPD-0240009 | C17: Keypad - 1.1 - CE140 | F17: ='Feb 2026'!AI17 -> 8 | AK17: =F17+SUM(G17:AH17) -> 8
A18: B2 | B18: KPD-0240010 | C18: Keypad - 1.1 - CE14H | F18: ='Feb 2026'!AI18 -> 9 | AK18: =F18+SUM(G18:AH18) -> 9
B19: KPD-0240011 | C19: Keypad - 1.1 - CE1230 | F19: ='Feb 2026'!AI19 -> 0 | AK19: =F19+SUM(G19:AH19) -> 0
A20: B1 | B20: KPD-0240012 | C20: Keypad - 1.1 - CE123H | F20: ='Feb 2026'!AI20 -> 239 | AK20: =F20+SUM(G20:AH20) -> 239
A21: B2 | B21: KPD-0240013 | C21: Keypad - 1.1 - CE1240 | F21: ='Feb 2026'!AI21 -> 9 | AK21: =F21+SUM(G21:AH21) -> 9
A22: B1 | B22: KPD-0240014 | C22: Keypad - 1.1 - CE124H | F22: ='Feb 2026'!AI22 -> 260 | AK22: =F22+SUM(G22:AH22) -> 260
A23: B2 | B23: KPD-0240015 | C23: Keypad - 1.1 - CE12430 | F23: ='Feb 2026'!AI23 -> 77 | AK23: =F23+SUM(G23:AH23) -> 77
A24: B2 | B24: KPD-0240016 | C24: Keypad - 1.1 - CE1234H | F24: ='Feb 2026'!AI24 -> 33 | AK24: =F24+SUM(G24:AH24) -> 33
A25: B2 | B25: KPD-0240017 | C25: Keypad - 3.1 - OE1(0/H) | F25: ='Feb 2026'!AI25 -> 477 | AK25: =F25+SUM(G25:AH25) -> 477
A26: B2 | B26: KPD-0240018 | C26: Keypad - 3.1 - OE12(0/H) | F26: ='Feb 2026'!AI26 -> 393 | AK26: =F26+SUM(G26:AH26) -> 393
A27: B3 | B27: KPD-0240019 | C27: Keypad - 3.1 - OE13(0/H) | F27: ='Feb 2026'!AI27 -> 66 | AK27: =F27+SUM(G27:AH27) -> 66
A28: B3 | B28: KPD-0240020 | C28: Keypad - 3.1 - OE14(0/H) | F28: ='Feb 2026'!AI28 -> 9 | AK28: =F28+SUM(G28:AH28) -> 9
A29: B2 | B29: KPD-0240021 | C29: Keypad - 3.1 - OE123(0/H) | F29: ='Feb 2026'!AI29 -> 8 | AK29: =F29+SUM(G29:AH29) -> 8
A30: B3 | B30: KPD-0240022 | C30: Keypad - 3.1 - OE124(0/H) | F30: ='Feb 2026'!AI30 -> 9 | AK30: =F30+SUM(G30:AH30) -> 9
A31: B3 | B31: KPD-0240023 | C31: Keypad - 3.1 - OE134(0/H) | F31: ='Feb 2026'!AI31 -> 9 | AK31: =F31+SUM(G31:AH31) -> 9
... A41: B3 | B41: KPD-0240033 | C41: Keypad - 3.1 - TE10 | F41: ='Feb 2026'!AI41 -> 9 | AK41: =F41+SUM(G41:AH41) -> 9
A42: B3 | B42: KPD-0240034 | C42: Keypad - 3.1 - HH (P/E)1 | F42: ='Feb 2026'!AI42 -> 100 | N42: -79 | S42: -87 | AK42: =F42+SUM(G42:AH42) -> -66
A43: B3 | B43: KPD-0240035 | C43: Keypad - 3.1 - HH (P/E)12 | F43: ='Feb 2026'!AI43 -> 200 | L43: -2 | AK43: =F43+SUM(G43:AH43) -> 198
A44: B3 | B44: KPD-0240036 | C44: Keypad - 3.1 - HH (P/E)126 | F44: ='Feb 2026'!AI44 -> 63 | AK44: =F44+SUM(G44:AH44) -> 63
A45: B3 | C45: Keypad - 1.1 - ACK1234 | F45: ='Feb 2026'!AI45 -> 39 | AK45: =F45+SUM(G45:AH45) -> 39
A46: B3 | B46: STK-0300001 | C46: Sticker - 1.1 - C00H | F46: ='Feb 2026'!AI46 -> 66 | AK46: =F46+SUM(G46:AH46) -> 66
A47: B3 | B47: STK-0300002 | C47: Sticker - 1.1 - CP10 | F47: ='Feb 2026'!AI47 -> 15 | AK47: =F47+SUM(G47:AH47) -> 15
A48: B3 | B48: STK-0300003 | C48: Sticker - 1.1 - CP1H | F48: ='Feb 2026'!AI48 -> 41 | N48: -12 | AK48: =F48+SUM(G48:AH48) -> 29
B49: STK-0300004 | C49: Sticker - 1.1 - CP120 | F49: ='Feb 2026'!AI49 -> 0 | AK49: =F49+SUM(G49:AH49) -> 0
A50: B3 | B50: STK-0300005 | C50: Sticker - 1.1 - CP12H | F50: ='Feb 2026'!AI50 -> 56 | AK50: =F50+SUM(G50:AH50) -> 56
...
