Workbook
Name _Hlk122640495: 'Jan 2026'!$B$88
Name _Hlk122640495: 'March 2026'!$B$88
Name _Hlk126512593: 'Jan 2026'!#REF!
Name _Hlk126512593: 'March 2026'!#REF!

Sheet Jan 2026
E1: Teller Technologies Private Limited
E2: 2nd Floor, No.1 7th Cross, 2nd Block TC Palya Main Road CSB Bank ATM Akshaya Nagar Ramamurthi Nagar Bangalore-560016
E3: FORMS AND FORMATS
E4: Title: Stock Sheet
E5: Department | H5: STORES | K5: Version No. | M5: 0 | N5: Issued Date
E6: DOC. No. | H6: FM/STR/001 | K6: Supersedes | M6: NIL
E7: Next Review Date | K7: Effective date
A9: Type of Goods
A10: Storage Location | B10: Part Number | C10: Product Name | D10: Rate | E10: Unit | F10: Opening Stock | G10: 46023 | H10: 46024 | I10: 46025 | J10: 46026 | K10: 46027 | L10: 46028 | M10: 46029 | N10: 46030 | O10: 46031 | P10: 46032 | Q10: 46033 | R10: 46034 | S10: 46035 | T10: 46036 | U10: 46037 | V10: 46038 | W10: 46039 | X10: 46040 | Y10: 46041 | Z10: 46042 | AA10: 46043 | AB10: 46044 | AC10: 46045 | AD10: 46046 | AE10: 46047 | AF10: 46048 | AG10: 46049 | AH10: 46050 | AI10: 46051 | AJ10: 46052 | AK10: 46053 | AL10: Closing Stock | AM10: Minimum Stock | AN10: Re order level | AO10: Maximum Stock
A11: A5 | B11: PCB-0010001 | C11: PCB - General Purpose - Single Side | E11: Nos. | F11: 1 | AL11: =SUM(G11:AK11)+F11 -> 1
A12: A5 | B12: PCB-0010020 | C12: PCB - General Purpose - Double Side | E12: Nos. | F12: 0 | AL12: =SUM(G12:AK12)+F12 -> 0
A13: A1 | B13: PCB-0010002 | C13: PCB 1.0 - Bed Switch | E13: Nos. | F13: =457+27 -> 484 | AL13: =SUM(G13:AK13)+F13 -> 484
A14: A1 | B14: PCB-0010003 | C14: PCB 1.0 - Toilet Switch / Door Indicator | E14: Nos. | F14: 312 | AL14: =SUM(G14:AK14)+F14 -> 312
A15: A1 | B15: PCB-0010004 | C15: PCB 1.1 - Bed Switch | E15: Nos. | F15: 0 | AG15: -121 | AH15: 540 | AJ15: -7 | AL15: =SUM(G15:AK15)+F15 -> 412
A16: A1 | B16: PCB-0010011 | C16: PCB 3.0 - 19mm Switch | E16: Nos. | F16: 263 | AL16: =SUM(G16:AK16)+F16 -> 263
A17: A1 | B17: PCB-0010012 | C17: PCB 3.0 - Batt Opd | E17: Nos. | F17: 213 | AL17: =SUM(G17:AK17)+F17 -> 213
A18: A1 | B18: PCB-0010014 | C18: PCB 3.0 - Door Indicator | E18: Nos. | F18: =226-9 -> 217 | L18: -69 | S18: -12 | AB18: -12 | AC18: -20 | AL18: =SUM(G18:AK18)+F18 -> 104
A19: A1 | B19: PCB-0010015 | C19: PCB 3.0 - Door Indicator - Sparsh | E19: Nos. | F19: 19 | AL19: =SUM(G19:AK19)+F19 -> 19
B20: PCB-0010016 | C20: PCB 3.0 - Handheld | E20: Nos. | F20: 505 | AL20: =SUM(G20:AK20)+F20 -> 505
A21: A1 | B21: PCB-0010017 | C21: PCB 3.0 - Toilet Switch | E21: Nos. | F21: 323 | H21: -12 | L21: -37 | S21: -12 | V21: -14 | AB21: -13 | AC21: -20 | AJ21: -7 | AL21: =SUM(G21:AK21)+F21 -> 208
A22: A1 | B22: PCB-0010018 | C22: PCB 3.1 - Bed Switch | E22: Nos. | F22: 22 | AL22: =SUM(G22:AK22)+F22 -> 22
B23: PCB-0010019 | C23: PCB 3.1 - Door Indicator - RGB | E23: Nos. | F23: 107 | AL23: =SUM(G23:AK23)+F23 -> 107
A24: A2 | B24: PCB-0015001 | C24: PCB SA - 1.0 BS w/o ESP, w/o P/S | E24: Nos. | F24: 48 | AL24: =SUM(G24:AK24)+F24 -> 48
A25: A2 | B25: PCB-0015002 | C25: PCB SA - 3.0 BS w/o ESP, w/o P/S | E25: Nos. | F25: 18 | AL25: =SUM(G25:AK25)+F25 -> 18
A26: A2 | B26: PCB-0015003 | C26: PCB SA - 1.1 BS w/o ESP, w/o P/S | E26: Nos. | AL26: =SUM(G26:AK26)+F26 -> 0
A27: A2 | B27: PCB-0015004 | C27: PCB SA - 1.1 BS w/o ESP, with P/S | E27: Nos. | AL27: =SUM(G27:AK27)+F27 -> 0
A28: A2 | B28: PCB-0015005 | C28: PCB SA - 1.1 BS with ESP, w/o P/S | E28: Nos. | AL28: =SUM(G28:AK28)+F28 -> 0
A29: A2 | B29: PCB-0015006 | C29: PCB SA - 1.1 BS with ESP, with P/S | E29: Nos. | AL29: =SUM(G29:AK29)+F29 -> 0
A30: A3 | B30: PCB-0015007 | C30: PCB SA - 3.0 TS w/o ESP, w/o P/S | E30: Nos. | F30: 8 | AL30: =SUM(G30:AK30)+F30 -> 8
A31: A3 | B31: PCB-0015008 | C31: PCB SA - 3.0 TS w/o ESP, with P/S | E31: Nos. | AL31: =SUM(G31:AK31)+F31 -> 0
A32: A3 | B32: PCB-0015009 | C32: PCB SA - 3.0 TS with ESP, w/o P/S | E32: Nos. | F32: 2 | AL32: =SUM(G32:AK32)+F32 -> 2
A33: A3 | B33: PCB-0015010 | C33: PCB SA - 3.0 TS with ESP, with P/S | E33: Nos. | AL33: =SUM(G33:AK33)+F33 -> 0
A34: A3 | B34: PCB-0015011 | C34: PCB SA - 3.0 DI w/o ESP, w/o P/S | E34: Nos. | F34: 4 | AL34: =SUM(G34:AK34)+F34 -> 4
A35: A3 | B35: PCB-0015012 | C35: PCB SA - 3.0 DI w/o ESP, with P/S | E35: Nos. | AL35: =SUM(G35:AK35)+F35 -> 0
A36: A3 | B36: PCB-0015013 | C36: PCB SA - 3.0 DI with ESP, w/o P/S | E36: Nos. | AL36: =SUM(G36:AK36)+F36 -> 0
A37: A3 | B37: PCB-0015014 | C37: PCB SA - 3.0 DI with ESP, with P/S | E37: Nos. | AL37: =SUM(G37:AK37)+F37 -> 0
A38: A3 | B38: PCB-0015015 | C38: PCB SA - 3.1 BS w/o ESP, w/o P/S | E38: Nos. | F38: 118 | AA38: -10 | AL38: =SUM(G38:AK38)+F38 -> 108
A39: A3 | B39: PCB-0015016 | C39: PCB SA - 3.1 BS w/o ESP, with P/S | E39: Nos. | AL39: =SUM(G39:AK39)+F39 -> 0
A40: A3 | B40: PCB-0015017 | C40: PCB SA - 3.1 BS with ESP, w/o P/S | E40: Nos. | AL40: =SUM(G40:AK40)+F40 -> 0
A41: A3 | B41: PCB-0015018 | C41: PCB SA - 3.1 BS with ESP, with P/S | E41: Nos. | F41: 1 | AL41: =SUM(G41:AK41)+F41 -> 1
...

Sheet Feb 2026
E1: Teller Technologies Private Limited
E2: 2nd Floor, No.1 7th Cross, 2nd Block TC Palya Main Road CSB Bank ATM Akshaya Nagar Ramamurthi Nagar Bangalore-560016
E3: FORMS AND FORMATS
E4: Title: Stock Sheet
E5: Department | H5: STORES | K5: Version No. | M5: 0 | N5: Issued Date
E6: DOC. No. | H6: FM/STR/001 | K6: Supersedes | M6: NIL
E7: Next Review Date | K7: Effective date
A9: Type of Goods
A10: Storage Location | B10: Part Number | C10: Product Name | D10: Rate | E10: Unit | F10: Opening Stock | G10: 46054 | H10: 46055 | I10: 46056 | J10: 46057 | K10: 46058 | L10: 46059 | M10: 46060 | N10: 46061 | O10: 46062 | P10: 46063 | Q10: 46064 | R10: 46065 | S10: 46066 | T10: 46067 | U10: 46068 | V10: 46069 | W10: 46070 | X10: 46071 | Y10: 46072 | Z10: 46073 | AA10: 46074 | AB10: 46075 | AC10: 46076 | AD10: 46077 | AE10: 46078 | AF10: 46079 | AG10: 46080 | AH10: 46081 | AI10: Closing Stock | AJ10: Minimum Stock | AK10: Re order level | AL10: Maximum Stock
A11: A6 | B11: PCB-0010001 | C11: PCB - General Purpose - Single Side | E11: Nos. | F11: ='Jan 2026'!AL11 -> 1 | AI11: =F11+SUM(G11:AH11) -> 1
A12: A6 | B12: PCB-0010020 | C12: PCB - General Purpose - Double Side | E12: Nos. | F12: ='Jan 2026'!AL12 -> 0 | AI12: =F12+SUM(G12:AH12) -> 0
A13: A1 | B13: PCB-0010002 | C13: PCB 1.0 - Bed Switch | E13: Nos. | F13: ='Jan 2026'!AL13 -> 484 | K13: -25 | Y13: -1 | AA13: -1 | AI13: =F13+SUM(G13:AH13) -> 457
A14: A1 | B14: PCB-0010003 | C14: PCB 1.0 - Toilet Switch / Door Indicator | E14: Nos. | F14: ='Jan 2026'!AL14 -> 312 | AI14: =F14+SUM(G14:AH14) -> 312
A15: A1 | B15: PCB-0010004 | C15: PCB 1.1 - Bed Switch | E15: Nos. | F15: ='Jan 2026'!AL15 -> 412 | H15: =-6 -> -6 | I15: -396 | K15: -9 | AI15: =F15+SUM(G15:AH15) -> 1
A16: A1 | B16: PCB-0010011 | C16: PCB 3.0 - 19mm Switch | E16: Nos. | F16: ='Jan 2026'!AL16 -> 263 | AI16: =F16+SUM(G16:AH16) -> 263
A17: A1 | B17: PCB-0010012 | C17: PCB 3.0 - Batt Opd | E17: Nos. | F17: ='Jan 2026'!AL17 -> 213 | J17: -2 | AI17: =F17+SUM(G17:AH17) -> 211
A18: A1 | B18: PCB-0010014 | C18: PCB 3.0 - Door Indicator | E18: Nos. | F18: ='Jan 2026'!AL18 -> 104 | J18: -8 | S18: -15 | Z18: -12 | AD18: -22 | AI18: =F18+SUM(G18:AH18) -> 47
A19: A1 | B19: PCB-0010015 | C19: PCB 3.0 - Door Indicator - Sparsh | E19: Nos. | F19: ='Jan 2026'!AL19 -> 19 | AI19: =F19+SUM(G19:AH19) -> 19
B20: PCB-0010016 | C20: PCB 3.0 - Handheld | E20: Nos. | F20: ='Jan 2026'!AL20 -> 505 | AI20: =F20+SUM(G20:AH20) -> 505
A21: A1 | B21: PCB-0010017 | C21: PCB 3.0 - Toilet Switch | E21: Nos. | F21: ='Jan 2026'!AL21 -> 208 | J21: -8 | K21: =-6+-9 -> -15 | L21: -10 | S21: -15 | Z21: =-22+-12 -> -34 | AD21: -22 | AI21: =F21+SUM(G21:AH21) -> 104
A22: A1 | B22: PCB-0010018 | C22: PCB 3.1 - Bed Switch | E22: Nos. | F22: ='Jan 2026'!AL22 -> 22 | AI22: =F22+SUM(G22:AH22) -> 22
B23: PCB-0010019 | C23: PCB 3.1 - Door Indicator - RGB | E23: Nos. | F23: ='Jan 2026'!AL23 -> 107 | AI23: =F23+SUM(G23:AH23) -> 107
A24: A2 | B24: PCB-0015001 | C24: PCB SA - 1.0 BS w/o ESP, w/o P/S | E24: Nos. | F24: ='Jan 2026'!AL24 -> 48 | AI24: =F24+SUM(G24:AH24) -> 48
A25: A2 | B25: PCB-0015002 | C25: PCB SA - 3.0 BS w/o ESP, w/o P/S | E25: Nos. | F25: ='Jan 2026'!AL25 -> 18 | AI25: =F25+SUM(G25:AH25) -> 18
A26: A2 | B26: PCB-0015003 | C26: PCB SA - 1.1 BS w/o ESP, w/o P/S | E26: Nos. | F26: ='Jan 2026'!AL26 -> 0 | K26: 396 | S26: -31 | Y26: -21 | Z26: -18 | AC26: -36 | AD26: -22 | AG26: -87 | AH26: 8 | AI26: =F26+SUM(G26:AH26) -> 189
A27: A2 | B27: PCB-0015004 | C27: PCB SA - 1.1 BS w/o ESP, with P/S | E27: Nos. | F27: ='Jan 2026'!AL27 -> 0 | AI27: =F27+SUM(G27:AH27) -> 0
A28: A2 | B28: PCB-0015005 | C28: PCB SA - 1.1 BS with ESP, w/o P/S | E28: Nos. | F28: ='Jan 2026'!AL28 -> 0 | AI28: =F28+SUM(G28:AH28) -> 0
A29: A2 | B29: PCB-0015006 | C29: PCB SA - 1.1 BS with ESP, with P/S | E29: Nos. | F29: ='Jan 2026'!AL29 -> 0 | AI29: =F29+SUM(G29:AH29) -> 0
A30: A3 | B30: PCB-0015007 | C30: PCB SA - 3.0 TS w/o ESP, w/o P/S | E30: Nos. | F30: ='Jan 2026'!AL30 -> 8 | AI30: =F30+SUM(G30:AH30) -> 8
A31: A3 | B31: PCB-0015008 | C31: PCB SA - 3.0 TS w/o ESP, with P/S | E31: Nos. | F31: ='Jan 2026'!AL31 -> 0 | AI31: =F31+SUM(G31:AH31) -> 0
A32: A3 | B32: PCB-0015009 | C32: PCB SA - 3.0 TS with ESP, w/o P/S | E32: Nos. | F32: ='Jan 2026'!AL32 -> 2 | AI32: =F32+SUM(G32:AH32) -> 2
A33: A3 | B33: PCB-0015010 | C33: PCB SA - 3.0 TS with ESP, with P/S | E33: Nos. | F33: ='Jan 2026'!AL33 -> 0 | AI33: =F33+SUM(G33:AH33) -> 0
A34: A3 | B34: PCB-0015011 | C34: PCB SA - 3.0 DI w/o ESP, w/o P/S | E34: Nos. | F34: ='Jan 2026'!AL34 -> 4 | AI34: =F34+SUM(G34:AH34) -> 4
A35: A3 | B35: PCB-0015012 | C35: PCB SA - 3.0 DI w/o ESP, with P/S | E35: Nos. | F35: ='Jan 2026'!AL35 -> 0 | AI35: =F35+SUM(G35:AH35) -> 0
A36: A3 | B36: PCB-0015013 | C36: PCB SA - 3.0 DI with ESP, w/o P/S | E36: Nos. | F36: ='Jan 2026'!AL36 -> 0 | AI36: =F36+SUM(G36:AH36) -> 0
A37: A3 | B37: PCB-0015014 | C37: PCB SA - 3.0 DI with ESP, with P/S | E37: Nos. | F37: ='Jan 2026'!AL37 -> 0 | AI37: =F37+SUM(G37:AH37) -> 0
A38: A3 | B38: PCB-0015015 | C38: PCB SA - 3.1 BS w/o ESP, w/o P/S | E38: Nos. | F38: ='Jan 2026'!AL38 -> 108 | L38: -21 | Z38: -12 | AI38: =F38+SUM(G38:AH38) -> 75
A39: A3 | B39: PCB-0015016 | C39: PCB SA - 3.1 BS w/o ESP, with P/S | E39: Nos. | F39: ='Jan 2026'!AL39 -> 0 | AI39: =F39+SUM(G39:AH39) -> 0
A40: A3 | B40: PCB-0015017 | C40: PCB SA - 3.1 BS with ESP, w/o P/S | E40: Nos. | F40: ='Jan 2026'!AL40 -> 0 | AI40: =F40+SUM(G40:AH40) -> 0
A41: A3 | B41: PCB-0015018 | C41: PCB SA - 3.1 BS with ESP, with P/S | E41: Nos. | F41: ='Jan 2026'!AL41 -> 1 | AI41: =F41+SUM(G41:AH41) -> 1
...

Sheet March 2026
E1: Teller Technologies Private Limited
E2: 2nd Floor, No.1 7th Cross, 2nd Block TC Palya Main Road CSB Bank ATM Akshaya Nagar Ramamurthi Nagar Bangalore-560016
E3: FORMS AND FORMATS
E4: Title: Stock Sheet
E5: Department | H5: STORES | K5: Version No. | M5: 0 | N5: Issued Date
E6: DOC. No. | H6: FM/STR/001 | K6: Supersedes | M6: NIL
E7: Next Review Date | K7: Effective date
A9: Type of Goods
A10: Storage Location | B10: Part Number | C10: Product Name | D10: Rate | E10: Unit | F10: Opening Stock | G10: 46082 | H10: 46083 | I10: 46084 | J10: 46085 | K10: 46086 | L10: 46087 | M10: 46088 | N10: 46089 | O10: 46090 | P10: 46091 | Q10: 46092 | R10: 46093 | S10: 46094 | T10: 46095 | U10: 46096 | V10: 46097 | W10: 46098 | X10: 46099 | Y10: 46100 | Z10: 46101 | AA10: 46102 | AB10: 46103 | AC10: 46104 | AD10: 46105 | AE10: 46106 | AF10: 46107 | AG10: 46108 | AH10: 46109 | AI10: 46110 | AJ10: 46111 | AK10: 46112 | AL10: Closing Stock | AM10: Minimum Stock | AN10: Re order level | AO10: Maximum Stock
A11: A6 | B11: PCB-0010001 | C11: PCB - General Purpose - Single Side | E11: Nos. | F11: ='Feb 2026'!AI11 -> 1 | Q11: -1 | AL11: =SUM(G11:AK11)+F11 -> 0 | AM11: 2 | AN11: 0 | AO11: 3
A12: A6 | B12: PCB-0010020 | C12: PCB - General Purpose - Double Side | E12: Nos. | F12: ='Feb 2026'!AI12 -> 0 | AL12: =SUM(G12:AK12)+F12 -> 0 | AM12: 2 | AN12: 0 | AO12: 3
A13: A1 | B13: PCB-0010002 | C13: PCB 1.0 - Bed Switch | E13: Nos. | F13: ='Feb 2026'!AI13 -> 457 | AL13: =SUM(G13:AK13)+F13 -> 457 | AP13: Not Currently Use
A14: A1 | B14: PCB-0010003 | C14: PCB 1.0 - Toilet Switch / Door Indicator | E14: Nos. | F14: ='Feb 2026'!AI14 -> 312 | AL14: =SUM(G14:AK14)+F14 -> 312 | AP14: Not Currently Use
A15: A1 | B15: PCB-0010004 | C15: PCB 1.1 - Bed Switch | E15: Nos. | F15: ='Feb 2026'!AI15 -> 1 | AL15: =SUM(G15:AK15)+F15 -> 1 | AM15: 180 | AN15: 300 | AO15: 1080
A16: A1 | B16: PCB-0010011 | C16: PCB 3.0 - 19mm Switch | E16: Nos. | F16: ='Feb 2026'!AI16 -> 263 | AL16: =SUM(G16:AK16)+F16 -> 263 | AP16: Not Currently Use
A17: A1 | B17: PCB-0010012 | C17: PCB 3.0 - Batt Opd | E17: Nos. | F17: ='Feb 2026'!AI17 -> 211 | AL17: =SUM(G17:AK17)+F17 -> 211 | AM17: 50 | AN17: 75 | AO17: 250
A18: A1 | B18: PCB-0010014 | C18: PCB 3.0 - Door Indicator | E18: Nos. | F18: ='Feb 2026'!AI18 -> 47 | L18: =-10+-14 -> -24 | AE18: -23 | AL18: =SUM(G18:AK18)+F18 -> 0 | AM18: 50 | AN18: 75 | AO18: 300
A19: A1 | B19: PCB-0010015 | C19: PCB 3.0 - Door Indicator - Sparsh | E19: Nos. | F19: ='Feb 2026'!AI19 -> 19 | AL19: =SUM(G19:AK19)+F19 -> 19 | AP19: Not Currently Use
B20: PCB-0010016 | C20: PCB 3.0 - Handheld | E20: Nos. | F20: ='Feb 2026'!AI20 -> 505 | AL20: =SUM(G20:AK20)+F20 -> 505 | AP20: Not Currently Use
A21: A1 | B21: PCB-0010017 | C21: PCB 3.0 - Toilet Switch | E21: Nos. | F21: ='Feb 2026'!AI21 -> 104 | K21: =-14+-23 -> -37 | AJ21: -42 | AL21: =SUM(G21:AK21)+F21 -> 25 | AM21: 50 | AN21: 75 | AO21: 300
A22: A1 | B22: PCB-0010018 | C22: PCB 3.1 - Bed Switch | E22: Nos. | F22: ='Feb 2026'!AI22 -> 22 | AL22: =SUM(G22:AK22)+F22 -> 22 | AM22: 150 | AN22: 250 | AO22: 450
B23: PCB-0010019 | C23: PCB 3.1 - Door Indicator - RGB | E23: Nos. | F23: ='Feb 2026'!AI23 -> 107 | AL23: =SUM(G23:AK23)+F23 -> 107 | AM23: 25 | AN23: 50 | AO23: 125
A24: A2 | B24: PCB-0015001 | C24: PCB SA - 1.0 BS w/o ESP, w/o P/S | E24: Nos. | F24: ='Feb 2026'!AI24 -> 48 | AL24: =SUM(G24:AK24)+F24 -> 48
A25: A2 | B25: PCB-0015002 | C25: PCB SA - 3.0 BS w/o ESP, w/o P/S | E25: Nos. | F25: ='Feb 2026'!AI25 -> 18 | AK25: -4 | AL25: =SUM(G25:AK25)+F25 -> 14
A26: A2 | B26: PCB-0015003 | C26: PCB SA - 1.1 BS w/o ESP, w/o P/S | E26: Nos. | F26: ='Feb 2026'!AI26 -> 189 | I26: -43 | K26: =-14+-36 -> -50 | Q26: -19 | V26: -1 | W26: -29 | Z26: -2 | AA26: -6 | AD26: -20 | AG26: -1 | AJ26: -2 | AL26: =SUM(G26:AK26)+F26 -> 16
A27: A2 | B27: PCB-0015004 | C27: PCB SA - 1.1 BS w/o ESP, with P/S | E27: Nos. | F27: ='Feb 2026'!AI27 -> 0 | AL27: =SUM(G27:AK27)+F27 -> 0
A28: A2 | B28: PCB-0015005 | C28: PCB SA - 1.1 BS with ESP, w/o P/S | E28: Nos. | F28: ='Feb 2026'!AI28 -> 0 | AL28: =SUM(G28:AK28)+F28 -> 0
A29: A2 | B29: PCB-0015006 | C29: PCB SA - 1.1 BS with ESP, with P/S | E29: Nos. | F29: ='Feb 2026'!AI29 -> 0 | AL29: =SUM(G29:AK29)+F29 -> 0
A30: A3 | B30: PCB-0015007 | C30: PCB SA - 3.0 TS w/o ESP, w/o P/S | E30: Nos. | F30: ='Feb 2026'!AI30 -> 8 | AL30: =SUM(G30:AK30)+F30 -> 8
A31: A3 | B31: PCB-0015008 | C31: PCB SA - 3.0 TS w/o ESP, with P/S | E31: Nos. | F31: ='Feb 2026'!AI31 -> 0 | AL31: =SUM(G31:AK31)+F31 -> 0
A32: A3 | B32: PCB-0015009 | C32: PCB SA - 3.0 TS with ESP, w/o P/S | E32: Nos. | F32: ='Feb 2026'!AI32 -> 2 | AL32: =SUM(G32:AK32)+F32 -> 2
A33: A3 | B33: PCB-0015010 | C33: PCB SA - 3.0 TS with ESP, with P/S | E33: Nos. | F33: ='Feb 2026'!AI33 -> 0 | AL33: =SUM(G33:AK33)+F33 -> 0
A34: A3 | B34: PCB-0015011 | C34: PCB SA - 3.0 DI w/o ESP, w/o P/S | E34: Nos. | F34: ='Feb 2026'!AI34 -> 4 | AL34: =SUM(G34:AK34)+F34 -> 4
A35: A3 | B35: PCB-0015012 | C35: PCB SA - 3.0 DI w/o ESP, with P/S | E35: Nos. | F35: ='Feb 2026'!AI35 -> 0 | AL35: =SUM(G35:AK35)+F35 -> 0
A36: A3 | B36: PCB-0015013 | C36: PCB SA - 3.0 DI with ESP, w/o P/S | E36: Nos. | F36: ='Feb 2026'!AI36 -> 0 | AL36: =SUM(G36:AK36)+F36 -> 0
A37: A3 | B37: PCB-0015014 | C37: PCB SA - 3.0 DI with ESP, with P/S | E37: Nos. | F37: ='Feb 2026'!AI37 -> 0 | V37: 7 | AG37: -1 | AK37: -3 | AL37: =SUM(G37:AK37)+F37 -> 3
A38: A3 | B38: PCB-0015015 | C38: PCB SA - 3.1 BS w/o ESP, w/o P/S | E38: Nos. | F38: ='Feb 2026'!AI38 -> 75 | V38: -8 | AL38: =SUM(G38:AK38)+F38 -> 67
A39: A3 | B39: PCB-0015016 | C39: PCB SA - 3.1 BS w/o ESP, with P/S | E39: Nos. | F39: ='Feb 2026'!AI39 -> 0 | AL39: =SUM(G39:AK39)+F39 -> 0
A40: A3 | B40: PCB-0015017 | C40: PCB SA - 3.1 BS with ESP, w/o P/S | E40: Nos. | F40: ='Feb 2026'!AI40 -> 0 | AL40: =SUM(G40:AK40)+F40 -> 0
A41: A3 | B41: PCB-0015018 | C41: PCB SA - 3.1 BS with ESP, with P/S | E41: Nos. | F41: ='Feb 2026'!AI41 -> 1 | AL41: =SUM(G41:AK41)+F41 -> 1
...

Sheet April 2026
E1: Teller Technologies Private Limited
E2: 2nd Floor, No.1 7th Cross, 2nd Block TC Palya Main Road CSB Bank ATM Akshaya Nagar Ramamurthi Nagar Bangalore-560016
E3: FORMS AND FORMATS
E4: Title: Stock Sheet
E5: Department | H5: STORES | K5: Version No. | M5: 0 | N5: Issued Date
E6: DOC. No. | H6: FM/STR/001 | K6: Supersedes | M6: NIL
E7: Next Review Date | K7: Effective date
A9: Type of Goods
A10: Storage Location | B10: Part Number | C10: Product Name | D10: Rate | E10: Unit | F10: Opening Stock | G10: 46113 | H10: 46114 | I10: 46115 | J10: 46116 | K10: 46117 | L10: 46118 | M10: 46119 | N10: 46120 | O10: 46121 | P10: 46122 | Q10: 46123 | R10: 46124 | S10: 46125 | T10: 46126 | U10: 46127 | V10: 46128 | W10: 46129 | X10: 46130 | Y10: 46131 | Z10: 46132 | AA10: 46133 | AB10: 46134 | AC10: 46135 | AD10: 46136 | AE10: 46137 | AF10: 46138 | AG10: 46139 | AH10: 46140 | AI10: 46141 | AJ10: 46142 | AK10: Closing Stock | AL10: Minimum Stock | AM10: Re order level | AN10: Maximum Stock
A11: A6 | B11: PCB-0010001 | C11: PCB - General Purpose - Single Side | E11: Nos. | F11: ='March 2026'!AL11 -> 0 | AK11: =SUM(G11:AJ11)+F11 -> 0 | AL11: 2 | AM11: 0 | AN11: 3
A12: A6 | B12: PCB-0010020 | C12: PCB - General Purpose - Double Side | E12: Nos. | F12: ='March 2026'!AL12 -> 0 | AK12: =SUM(G12:AJ12)+F12 -> 0 | AL12: 2 | AM12: 0 | AN12: 3
A13: A1 | B13: PCB-0010002 | C13: PCB 1.0 - Bed Switch | E13: Nos. | F13: ='March 2026'!AL13 -> 457 | AK13: =SUM(G13:AJ13)+F13 -> 457 | AO13: Not Currently Use
A14: A1 | B14: PCB-0010003 | C14: PCB 1.0 - Toilet Switch / Door Indicator | E14: Nos. | F14: ='March 2026'!AL14 -> 312 | AK14: =SUM(G14:AJ14)+F14 -> 312 | AO14: Not Currently Use
A15: A1 | B15: PCB-0010004 | C15: PCB 1.1 - Bed Switch | E15: Nos. | F15: ='March 2026'!AL15 -> 1 | N15: 1350 | AK15: =SUM(G15:AJ15)+F15 -> 1351 | AL15: 180 | AM15: 300 | AN15: 1080
A16: A1 | B16: PCB-0010011 | C16: PCB 3.0 - 19mm Switch | E16: Nos. | F16: ='March 2026'!AL16 -> 263 | AK16: =SUM(G16:AJ16)+F16 -> 263 | AO16: Not Currently Use
A17: A1 | B17: PCB-0010012 | C17: PCB 3.0 - Batt Opd | E17: Nos. | F17: ='March 2026'!AL17 -> 211 | G17: -27 | AK17: =SUM(G17:AJ17)+F17 -> 184 | AL17: 50 | AM17: 75 | AN17: 250
A18: A1 | B18: PCB-0010014 | C18: PCB 3.0 - Door Indicator | E18: Nos. | F18: ='March 2026'!AL18 -> 0 | N18: 300 | AK18: =SUM(G18:AJ18)+F18 -> 300 | AL18: 50 | AM18: 75 | AN18: 300
A19: A1 | B19: PCB-0010015 | C19: PCB 3.0 - Door Indicator - Sparsh | E19: Nos. | F19: ='March 2026'!AL19 -> 19 | AK19: =SUM(G19:AJ19)+F19 -> 19 | AO19: Not Currently Use
B20: PCB-0010016 | C20: PCB 3.0 - Handheld | E20: Nos. | F20: ='March 2026'!AL20 -> 505 | AK20: =SUM(G20:AJ20)+F20 -> 505 | AO20: Not Currently Use
A21: A1 | B21: PCB-0010017 | C21: PCB 3.0 - Toilet Switch | E21: Nos. | F21: ='March 2026'!AL21 -> 25 | I21: -25 | N21: 300 | AK21: =SUM(G21:AJ21)+F21 -> 300 | AL21: 50 | AM21: 75 | AN21: 300
A22: A1 | B22: PCB-0010018 | C22: PCB 3.1 - Bed Switch | E22: Nos. | F22: ='March 2026'!AL22 -> 22 | I22: -23 | N22: 300 | AK22: =SUM(G22:AJ22)+F22 -> 299 | AL22: 150 | AM22: 250 | AN22: 450
B23: PCB-0010019 | C23: PCB 3.1 - Door Indicator - RGB | E23: Nos. | F23: ='March 2026'!AL23 -> 107 | AK23: =SUM(G23:AJ23)+F23 -> 107 | AL23: 25 | AM23: 50 | AN23: 125
A24: A2 | B24: PCB-0015001 | C24: PCB SA - 1.0 BS w/o ESP, w/o P/S | E24: Nos. | F24: ='March 2026'!AL24 -> 48 | AK24: =SUM(G24:AJ24)+F24 -> 48
A25: A2 | B25: PCB-0015002 | C25: PCB SA - 3.0 BS w/o ESP, w/o P/S | E25: Nos. | F25: ='March 2026'!AL25 -> 14 | AK25: =SUM(G25:AJ25)+F25 -> 14
A26: A2 | B26: PCB-0015003 | C26: PCB SA - 1.1 BS w/o ESP, w/o P/S | E26: Nos. | F26: ='March 2026'!AL26 -> 16 | AK26: =SUM(G26:AJ26)+F26 -> 16
A27: A2 | B27: PCB-0015004 | C27: PCB SA - 1.1 BS w/o ESP, with P/S | E27: Nos. | F27: ='March 2026'!AL27 -> 0 | AK27: =SUM(G27:AJ27)+F27 -> 0
A28: A2 | B28: PCB-0015005 | C28: PCB SA - 1.1 BS with ESP, w/o P/S | E28: Nos. | F28: ='March 2026'!AL28 -> 0 | AK28: =SUM(G28:AJ28)+F28 -> 0
A29: A2 | B29: PCB-0015006 | C29: PCB SA - 1.1 BS with ESP, with P/S | E29: Nos. | F29: ='March 2026'!AL29 -> 0 | AK29: =SUM(G29:AJ29)+F29 -> 0
A30: A3 | B30: PCB-0015007 | C30: PCB SA - 3.0 TS w/o ESP, w/o P/S | E30: Nos. | F30: ='March 2026'!AL30 -> 8 | AK30: =SUM(G30:AJ30)+F30 -> 8
A31: A3 | B31: PCB-0015008 | C31: PCB SA - 3.0 TS w/o ESP, with P/S | E31: Nos. | F31: ='March 2026'!AL31 -> 0 | AK31: =SUM(G31:AJ31)+F31 -> 0
A32: A3 | B32: PCB-0015009 | C32: PCB SA - 3.0 TS with ESP, w/o P/S | E32: Nos. | F32: ='March 2026'!AL32 -> 2 | AK32: =SUM(G32:AJ32)+F32 -> 2
A33: A3 | B33: PCB-0015010 | C33: PCB SA - 3.0 TS with ESP, with P/S | E33: Nos. | F33: ='March 2026'!AL33 -> 0 | AK33: =SUM(G33:AJ33)+F33 -> 0
A34: A3 | B34: PCB-0015011 | C34: PCB SA - 3.0 DI w/o ESP, w/o P/S | E34: Nos. | F34: ='March 2026'!AL34 -> 4 | AK34: =SUM(G34:AJ34)+F34 -> 4
A35: A3 | B35: PCB-0015012 | C35: PCB SA - 3.0 DI w/o ESP, with P/S | E35: Nos. | F35: ='March 2026'!AL35 -> 0 | AK35: =SUM(G35:AJ35)+F35 -> 0
... A37: A3 | B37: PCB-0015014 | C37: PCB SA - 3.0 DI with ESP, with P/S | E37: Nos. | F37: ='March 2026'!AL37 -> 3 | AK37: =SUM(G37:AJ37)+F37 -> 3
A38: A3 | B38: PCB-0015015 | C38: PCB SA - 3.1 BS w/o ESP, w/o P/S | E38: Nos. | F38: ='March 2026'!AL38 -> 67 | G38: -16 | AK38: =SUM(G38:AJ38)+F38 -> 51
A39: A3 | B39: PCB-0015016 | C39: PCB SA - 3.1 BS w/o ESP, with P/S | E39: Nos. | F39: ='March 2026'!AL39 -> 0 | AK39: =SUM(G39:AJ39)+F39 -> 0
A40: A3 | B40: PCB-0015017 | C40: PCB SA - 3.1 BS with ESP, w/o P/S | E40: Nos. | F40: ='March 2026'!AL40 -> 0 | AK40: =SUM(G40:AJ40)+F40 -> 0
A41: A3 | B41: PCB-0015018 | C41: PCB SA - 3.1 BS with ESP, with P/S | E41: Nos. | F41: ='March 2026'!AL41 -> 1 | AK41: =SUM(G41:AJ41)+F41 -> 1
A42: A3 | B42: PCB-0015022 | C42: PCB SA - 3.1 Door Indicator-RGB w/o ESP & w/o P/S | E42: Nos. | F42: ='March 2026'!AL42 -> 141 | AK42: =SUM(G42:AJ42)+F42 -> 141
...
